Workbook

Sheet L_Middens
A1: Identifier | B1: Identifier | C1: =FossilMiddens!I1 -> Longitude | D1: =FossilMiddens!H1 -> Latitude | E1: Elev (ADEM_1) | F1: Elev (9SecDEM) | G1: difference
A2: =FossilMiddens!A2 -> ARLTP5 | B2: Midden1 | C2: =FossilMiddens!I2 -> -23.45 | D2: =FossilMiddens!H2 -> 134.7 | E2: 660.017 | F2: 661.952 | G2: -1.935
A3: =FossilMiddens!A3 -> ARLT01 | B3: Midden2 | C3: =FossilMiddens!I3 -> -23.45 | D3: =FossilMiddens!H3 -> 134.7 | E3: 660.017 | F3: 661.952 | G3: -1.935
A4: =FossilMiddens!A4 -> ARLTN15 | B4: Midden3 | C4: =FossilMiddens!I4 -> -23.45 | D4: =FossilMiddens!H4 -> 134.7 | E4: 660.017 | F4: 661.952 | G4: -1.935
A5: =FossilMiddens!A5 -> ARLTH10 | B5: Midden4 | C5: =FossilMiddens!I5 -> -23.45 | D5: =FossilMiddens!H5 -> 134.7 | E5: 660.017 | F5: 661.952 | G5: -1.935
A6: =FossilMiddens!A6 -> ARLTK2 | B6: Midden5 | C6: =FossilMiddens!I6 -> -23.45 | D6: =FossilMiddens!H6 -> 134.7 | E6: 660.017 | F6: 661.952 | G6: -1.935
A7: =FossilMiddens!A7 -> ARLTG8 | B7: Midden6 | C7: =FossilMiddens!I7 -> -23.45 | D7: =FossilMiddens!H7 -> 134.7 | E7: 660.017 | F7: 661.952 | G7: -1.935
A8: =FossilMiddens!A8 -> FinkeG15 | B8: Midden7 | C8: =FossilMiddens!I8 -> -24.433333 | D8: =FossilMiddens!H8 -> 132.2 | E8: 593.999 | F8: 558.437 | G8: 35.562
A9: =FossilMiddens!A9 -> FinkeI16 | B9: Midden8 | C9: =FossilMiddens!I9 -> -24.433333 | D9: =FossilMiddens!H9 -> 132.2 | E9: 593.999 | F9: 558.437 | G9: 35.562
A10: =FossilMiddens!A10 -> FinkeA22 | B10: Midden9 | C10: =FossilMiddens!I10 -> -24.433333 | D10: =FossilMiddens!H10 -> 132.2 | E10: 593.999 | F10: 558.437 | G10: 35.562
A11: =FossilMiddens!A11 -> FinkeH19 | B11: Midden10 | C11: =FossilMiddens!I11 -> -24.433333 | D11: =FossilMiddens!H11 -> 132.2 | E11: 593.999 | F11: 558.437 | G11: 35.562
A12: =FossilMiddens!A12 -> FinkeF4 | B12: Midden11 | C12: =FossilMiddens!I12 -> -24.433333 | D12: =FossilMiddens!H12 -> 132.2 | E12: 593.999 | F12: 558.437 | G12: 35.562
A13: =FossilMiddens!A14 -> Nelson et al (1990) , | B13: Midden12 | C13: =FossilMiddens!I14 -> -24 | D13: =FossilMiddens!H14 -> 133 | E13: 653.97 | F13: 632.971 | G13: 20.999
A14: =FossilMiddens!A15 -> Nelson et al (1990) , | B14: Midden13 | C14: =FossilMiddens!I15 -> -24 | D14: =FossilMiddens!H15 -> 133 | E14: 653.97 | F14: 632.971 | G14: 20.999
A15: =FossilMiddens!A16 -> M0236 | B15: Midden14 | C15: =FossilMiddens!I16 -> -30.5 | D15: =FossilMiddens!H16 -> 119.66667 | E15: 625.002 | F15: 434.713 | G15: 190.289
A16: =FossilMiddens!A17 -> CRA9 | B16: Midden15 | C16: =FossilMiddens!I17 -> -23.5 | D16: =FossilMiddens!H17 -> 134.5 | E16: 610.019 | F16: 599.413 | G16: 10.606
A17: =FossilMiddens!A18 -> Berry (1993) | B17: Midden16 | C17: =FossilMiddens!I18 -> -24.316667 | D17: =FossilMiddens!H18 -> 131.68333 | E17: 650.006 | F17: 736.634 | G17: -86.628
A18: =FossilMiddens!A19 -> Berry (1993) | B18: Midden17 | C18: =FossilMiddens!I19 -> -24.316667 | D18: =FossilMiddens!H19 -> 131.68333 | E18: 650.006 | F18: 736.634 | G18: -86.628
A19: =FossilMiddens!A20 -> M0505 | B19: Midden18 | C19: =FossilMiddens!I20 -> -25.05 | D19: =FossilMiddens!H20 -> 124.98333 | E19: 546.001 | F19: 531.355 | G19: 14.646
A20: =FossilMiddens!A21 -> M05170b | B20: Midden19 | C20: =FossilMiddens!I21 -> -25.05 | D20: =FossilMiddens!H21 -> 124.98333 | E20: 546.001 | F20: 531.355 | G20: 14.646
A21: =FossilMiddens!A22 -> M06 | B21: Midden20 | C21: =FossilMiddens!I22 -> -25.05 | D21: =FossilMiddens!H22 -> 124.98333 | E21: 546.001 | F21: 531.355 | G21: 14.646
A22: =FossilMiddens!A23 -> M0652 | B22: Midden21 | C22: =FossilMiddens!I23 -> -25.05 | D22: =FossilMiddens!H23 -> 124.98333 | E22: 546.001 | F22: 531.355 | G22: 14.646
A23: =FossilMiddens!A24 -> M07 | B23: Midden22 | C23: =FossilMiddens!I24 -> -25.05 | D23: =FossilMiddens!H24 -> 124.98333 | E23: 546.001 | F23: 531.355 | G23: 14.646
A24: =FossilMiddens!A25 -> M07 | B24: Midden23 | C24: =FossilMiddens!I25 -> -25.05 | D24: =FossilMiddens!H25 -> 124.98333 | E24: 546.001 | F24: 531.355 | G24: 14.646
... A155: =FossilMiddens!A156 -> GH1 (base) | B155: Midden154 | C155: =FossilMiddens!I156 -> -31.166667 | D155: =FossilMiddens!H156 -> 142.6 | E155: 326.945 | F155: 234.84 | G155: 92.105
B156: Midden155 | C156: -31.95 | D156: 149.267 | E156: 547.829 | F156: 0 | G156: 547.829
A157: Cole2000 | B157: Leporillus midden | C157: -23.2666 | D157: 134.39998 | E157: 785.083 | F157: 676.114 | G157: 108.969
A158: Cole2000 | B158: Leporillus midden | C158: -23.61664 | D158: 134.33332 | E158: 561.036 | F158: 616.903 | G158: -55.867
A159: Cole2000 | B159: Leporillus midden | C159: -22 | D159: 137.25167 | E159: 251.804 | F159: 262.938 | G159: -11.134
A160: Cole2000 | B160: Leporillus midden | C160: -22.004444 | D160: 137.32056 | E160: 246.241 | F160: 259.07 | G160: -12.829
A161: 12622 | B161: Leporillus sp. | C161: -25.066672 | D161: 124.99999 | E161: 548.999 | F161: 498.695 | G161: 50.304
A162: 12623 | B162: Leporillus sp. | C162: -25.183337 | D162: 125.06666 | E162: 557.018 | F162: 491.576 | G162: 65.442
A163: 12624 | B163: Leporillus sp. | C163: -25.550001 | D163: 125.29722 | E163: 521.673 | F163: 475.241 | G163: 46.432
A164: 12711 | B164: Leporillus sp. | C164: -31.016668 | D164: 125.33333 | E164: 182.985 | F164: 180.749 | G164: 2.236
A165: 12628 | B165: Leporillus sp. | C165: -26.961113 | D165: 125.41555 | E165: 473.343 | F165: 450.381 | G165: 22.962
A166: 12598 | B166: Leporillus sp. | C166: -25.716671 | D166: 125.5 | E166: 478.996 | F166: 425.757 | G166: 53.239
A167: 12625 | B167: Leporillus sp. | C167: -25.247227 | D167: 125.54999 | E167: 494.334 | F167: 403.16 | G167: 91.174
A168: 12593 | B168: Leporillus sp. | C168: -25.650006 | D168: 125.54999 | E168: 466.984 | F168: 449.518 | G168: 17.466
A169: 12673 | B169: Leporillus sp. | C169: -25.050002 | D169: 125.58333 | E169: 510.009 | F169: 482.952 | G169: 27.057
A170: 12649 | B170: Leporillus sp. | C170: -27.100004 | D170: 125.61667 | E170: 443.009 | F170: 394.404 | G170: 48.605
...

Sheet Lapicalis
A1: Identifier | B1: =FossilMiddens!I1 -> Longitude | C1: =FossilMiddens!H1 -> Latitude | D1: AUSDEM | E1: 9SECDEM | W1: Difference
A2: 12684 | B2: 136.16666 | C2: -33.43334 | D2: 238.977 | E2: =SUM(F2:V2) -> 436.517 | F2: 0 | G2: 0 | H2: 0 | I2: 0 | J2: 0 | K2: 0 | L2: 0 | M2: 0 | N2: 0 | O2: 0 | P2: 0 | Q2: 0 | R2: 0 | S2: 0 | T2: 436.517 | U2: 0 | V2: 0 | W2: =ABS(D2-E2) -> 197.54
A3: 12674 | B3: 132.16666 | C3: -30.86667 | D3: 150 | E3: =SUM(F3:V3) -> 86.1354 | F3: 0 | G3: 0 | H3: 0 | I3: 0 | J3: 0 | K3: 0 | L3: 0 | M3: 0 | N3: 0 | O3: 0 | P3: 0 | Q3: 0 | R3: 0 | S3: 86.1354 | T3: 0 | U3: 0 | V3: 0 | W3: =ABS(D3-E3) -> 63.8646
A4: 12688 | B4: 142.16666 | C4: -34.183342 | D4: 37.0179 | E4: =SUM(F4:V4) -> 36.9103 | F4: 0 | G4: 0 | H4: 0 | I4: 0 | J4: 0 | K4: 0 | L4: 0 | M4: 0 | N4: 0 | O4: 0 | P4: 0 | Q4: 0 | R4: 0 | S4: 0 | T4: 0 | U4: 36.9103 | V4: 0 | W4: =ABS(D4-E4) -> 0.1076
A5: 12575 | B5: 142.18333 | C5: -34.16667 | D5: 50.9764 | E5: =SUM(F5:V5) -> 51.8807 | F5: 0 | G5: 0 | H5: 0 | I5: 0 | J5: 0 | K5: 0 | L5: 0 | M5: 0 | N5: 0 | O5: 0 | P5: 0 | Q5: 0 | R5: 0 | S5: 0 | T5: 0 | U5: 51.8807 | V5: 0 | W5: =ABS(D5-E5) -> 0.9043
A6: 12659 | B6: 139.28333 | C6: -30.96667 | D6: 210.042 | E6: =SUM(F6:V6) -> 116.903 | F6: 0 | G6: 0 | H6: 0 | I6: 0 | J6: 0 | K6: 0 | L6: 0 | M6: 0 | N6: 0 | O6: 0 | P6: 0 | Q6: 0 | R6: 0 | S6: 0 | T6: 0 | U6: 0 | V6: 116.903 | W6: =ABS(D6-E6) -> 93.139
A7: 12661 | B7: 138.36666 | C7: -30.583334 | D7: 315.021 | E7: =SUM(F7:V7) -> 237.932 | F7: 0 | G7: 0 | H7: 0 | I7: 0 | J7: 0 | K7: 0 | L7: 0 | M7: 0 | N7: 0 | O7: 0 | P7: 0 | Q7: 0 | R7: 0 | S7: 0 | T7: 0 | U7: 0 | V7: 237.932 | W7: =ABS(D7-E7) -> 77.089
A8: 12678 | B8: 125.88333 | C8: -32.21667 | D8: 99.9854 | E8: =SUM(F8:V8) -> 80.2412 | F8: 0 | G8: 0 | H8: 0 | I8: 0 | J8: 0 | K8: 0 | L8: 0 | M8: 0 | N8: 0 | O8: 0 | P8: 80.2412 | Q8: 0 | R8: 0 | S8: 0 | T8: 0 | U8: 0 | V8: 0 | W8: =ABS(D8-E8) -> 19.7442
A9: 12738 | B9: 125.91667 | C9: -31.96667 | D9: 93.9787 | E9: =SUM(F9:V9) -> 98.8855 | F9: 0 | G9: 0 | H9: 0 | I9: 0 | J9: 0 | K9: 0 | L9: 0 | M9: 98.8855 | N9: 0 | O9: 0 | P9: 0 | Q9: 0 | R9: 0 | S9: 0 | T9: 0 | U9: 0 | V9: 0 | W9: =ABS(D9-E9) -> 4.9068
A10: 13233 | B10: 125.93333 | C10: -25.766668 | D10: 517.983 | E10: =SUM(F10:V10) -> 493.884 | F10: 0 | G10: 0 | H10: 0 | I10: 0 | J10: 493.884 | K10: 0 | L10: 0 | M10: 0 | N10: 0 | O10: 0 | P10: 0 | Q10: 0 | R10: 0 | S10: 0 | T10: 0 | U10: 0 | V10: 0 | W10: =ABS(D10-E10) -> 24.099
A11: 13235 | B11: 125.86667 | C11: -26.600004 | D11: 494.005 | E11: =SUM(F11:V11) -> 458.522 | F11: 0 | G11: 0 | H11: 0 | I11: 0 | J11: 458.522 | K11: 0 | L11: 0 | M11: 0 | N11: 0 | O11: 0 | P11: 0 | Q11: 0 | R11: 0 | S11: 0 | T11: 0 | U11: 0 | V11: 0 | W11: =ABS(D11-E11) -> 35.483
A12: 12695 | B12: 127.43333 | C12: -31.650001 | D12: 121.987 | E12: =SUM(F12:V12) -> 113.096 | F12: 0 | G12: 0 | H12: 0 | I12: 0 | J12: 0 | K12: 0 | L12: 0 | M12: 0 | N12: 113.096 | O12: 0 | P12: 0 | Q12: 0 | R12: 0 | S12: 0 | T12: 0 | U12: 0 | V12: 0 | W12: =ABS(D12-E12) -> 8.891
A13: 12700 | B13: 130.66666 | C13: -26.616673 | D13: 709.018 | E13: =SUM(F13:V13) -> 550.35 | F13: 0 | G13: 0 | H13: 0 | I13: 0 | J13: 0 | K13: 550.35 | L13: 0 | M13: 0 | N13: 0 | O13: 0 | P13: 0 | Q13: 0 | R13: 0 | S13: 0 | T13: 0 | U13: 0 | V13: 0 | W13: =ABS(D13-E13) -> 158.668
... A39: 13237 | B39: 126.46666 | C39: -27.200002 | D39: 501.987 | E39: =SUM(F39:V39) -> 475.076 | F39: 0 | G39: 0 | H39: 0 | I39: 0 | J39: 0 | K39: 475.076 | L39: 0 | M39: 0 | N39: 0 | O39: 0 | P39: 0 | Q39: 0 | R39: 0 | S39: 0 | T39: 0 | U39: 0 | V39: 0 | W39: =ABS(D39-E39) -> 26.911

Sheet Lconditor
A1: Identifier | D1: =FossilMiddens!I1 -> Longitude | E1: =FossilMiddens!H1 -> Latitude | F1: AUSDEM | G1: 9SECDEM | R1: Difference | Y1: Difference
A2: Baynes2002 | B2: LcBaynes2002 | C2: Leporillus conditor | D2: 112.95 | E2: -25.75 | F2: 0 | G2: =SUM(H2:X2) -> 0 | H2: 0 | I2: 0 | J2: 0 | K2: 0 | L2: 0 | M2: 0 | N2: 0 | O2: 0 | P2: 0 | Q2: 0 | R2: 0 | S2: 0 | T2: 0 | U2: 0 | V2: 0 | W2: 0 | X2: 0 | Y2: =ABS(F2-G2) -> 0
A3: Baynes2002 | B3: LcBaynes2002 | C3: Leporillus conditor | D3: 113.1 | E3: -25.967 | F3: 41.5237 | G3: =SUM(H3:X3) -> 98.9883 | H3: 0 | I3: 0 | J3: 0 | K3: 98.9883 | L3: 0 | M3: 0 | N3: 0 | O3: 0 | P3: 0 | Q3: 0 | R3: 0 | S3: 0 | T3: 0 | U3: 0 | V3: 0 | W3: 0 | X3: 0 | Y3: =ABS(F3-G3) -> 57.4646
A4: Baynes2002 | B4: LcBaynes2002 | C4: Leporillus conditor | D4: 113.3 | E4: -26.4 | F4: 0.986557 | G4: =SUM(H4:X4) -> 0.949936 | H4: 0 | I4: 0 | J4: 0 | K4: 0.949936 | L4: 0 | M4: 0 | N4: 0 | O4: 0 | P4: 0 | Q4: 0 | R4: 0 | S4: 0 | T4: 0 | U4: 0 | V4: 0 | W4: 0 | X4: 0 | Y4: =ABS(F4-G4) -> 0.036621
A5: Baynes2002 | B5: LcBaynes2002 | C5: Leporillus conditor | D5: 113.433 | E5: -24.117 | F5: 9.7083 | G5: =SUM(H5:X5) -> 22.6143 | H5: 0 | I5: 0 | J5: 0 | K5: 22.6143 | L5: 0 | M5: 0 | N5: 0 | O5: 0 | P5: 0 | Q5: 0 | R5: 0 | S5: 0 | T5: 0 | U5: 0 | V5: 0 | W5: 0 | X5: 0 | Y5: =ABS(F5-G5) -> 12.906
A6: Baynes2002 | B6: LcBaynes2002 | C6: Leporillus conditor | D6: 113.583 | E6: -25.633 | F6: 0 | G6: =SUM(H6:X6) -> 0.190319 | H6: 0 | I6: 0 | J6: 0 | K6: 0.190319 | L6: 0 | M6: 0 | N6: 0 | O6: 0 | P6: 0 | Q6: 0 | R6: 0 | S6: 0 | T6: 0 | U6: 0 | V6: 0 | W6: 0 | X6: 0 | Y6: =ABS(F6-G6) -> 0.190319
A7: Baynes2002 | B7: LcBaynes2002 | C7: Leporillus conditor | D7: 113.683 | E7: -26.6 | F7: 0 | G7: =SUM(H7:X7) -> 0 | H7: 0 | I7: 0 | J7: 0 | K7: 0 | L7: 0 | M7: 0 | N7: 0 | O7: 0 | P7: 0 | Q7: 0 | R7: 0 | S7: 0 | T7: 0 | U7: 0 | V7: 0 | W7: 0 | X7: 0 | Y7: =ABS(F7-G7) -> 0
A8: Baynes2002 | B8: LcBaynes2002 | C8: Leporillus conditor | D8: 113.8 | E8: -23.117 | F8: 11.1491 | G8: =SUM(H8:X8) -> 9.92582 | H8: 9.92582 | I8: 0 | J8: 0 | K8: 0 | L8: 0 | M8: 0 | N8: 0 | O8: 0 | P8: 0 | Q8: 0 | R8: 0 | S8: 0 | T8: 0 | U8: 0 | V8: 0 | W8: 0 | X8: 0 | Y8: =ABS(F8-G8) -> 1.22328
A9: Baynes2002 | B9: LcBaynes2002 | C9: Leporillus conditor | D9: 114.1 | E9: -27.833 | F9: 10.8253 | G9: =SUM(H9:X9) -> 0 | H9: 0 | I9: 0 | J9: 0 | K9: 0 | L9: 0 | M9: 0 | N9: 0 | O9: 0 | P9: 0 | Q9: 0 | R9: 0 | S9: 0 | T9: 0 | U9: 0 | V9: 0 | W9: 0 | X9: 0 | Y9: =ABS(F9-G9) -> 10.8253
A10: Baynes2002 | B10: LcBaynes2002 | C10: Leporillus conditor | D10: 114.283 | E10: -25.983 | F10: 20.8087 | G10: =SUM(H10:X10) -> 7.89932 | H10: 0 | I10: 0 | J10: 0 | K10: 7.89932 | L10: 0 | M10: 0 | N10: 0 | O10: 0 | P10: 0 | Q10: 0 | R10: 0 | S10: 0 | T10: 0 | U10: 0 | V10: 0 | W10: 0 | X10: 0 | Y10: =ABS(F10-G10) -> 12.90938
A11: Baynes2002 | B11: LcBaynes2002 | C11: Leporillus conditor | D11: 115.617 | E11: -28.117 | F11: 379.115 | G11: =SUM(H11:X11) -> 304.026 | H11: 0 | I11: 0 | J11: 0 | K11: 0 | L11: 0 | M11: 0 | N11: 304.026 | O11: 0 | P11: 0 | Q11: 0 | R11: 0 | S11: 0 | T11: 0 | U11: 0 | V11: 0 | W11: 0 | X11: 0 | Y11: =ABS(F11-G11) -> 75.089
A12: Baynes2002 | B12: LcBaynes2002 | C12: Leporillus conditor | D12: 117.183 | E12: -28.133 | F12: 460.302 | G12: =SUM(H12:X12) -> 462.271 | H12: 0 | I12: 0 | J12: 0 | K12: 0 | L12: 0 | M12: 0 | N12: 462.271 | O12: 0 | P12: 0 | Q12: 0 | R12: 0 | S12: 0 | T12: 0 | U12: 0 | V12: 0 | W12: 0 | X12: 0 | Y12: =ABS(F12-G12) -> 1.969
A13: Baynes2002 | B13: LcBaynes2002 | C13: Leporillus conditor | D13: 117.7 | E13: -26.917 | F13: 634.788 | G13: =SUM(H13:X13) -> 537.689 | H13: 0 | I13: 0 | J13: 0 | K13: 537.689 | L13: 0 | M13: 0 | N13: 0 | O13: 0 | P13: 0 | Q13: 0 | R13: 0 | S13: 0 | T13: 0 | U13: 0 | V13: 0 | W13: 0 | X13: 0 | Y13: =ABS(F13-G13) -> 97.099
... A18: Baynes2002 | B18: LcBaynes2002 | C18: Leporillus conditor | D18: 121.633 | E18: -29.517 | F18: 398.957 | G18: =SUM(H18:X18) -> 454.352 | H18: 0 | I18: 0 | J18: 0 | K18: 0 | L18: 0 | M18: 0 | N18: 0 | O18: 454.352 | P18: 0 | Q18: 0 | R18: 0 | S18: 0 | T18: 0 | U18: 0 | V18: 0 | W18: 0 | X18: 0 | Y18: =ABS(F18-G18) -> 55.395
A19: 12708 | B19: Lc12708 | C19: Leporillus conditor | D19: 125.33333 | E19: -31.066673 | F19: 179.98 | G19: =SUM(H19:X19) -> 174.398 | H19: 0 | I19: 0 | J19: 0 | K19: 0 | L19: 0 | M19: 0 | N19: 0 | O19: 174.398 | P19: 0 | Q19: 0 | R19: 0 | S19: 0 | T19: 0 | U19: 0 | V19: 0 | W19: 0 | X19: 0 | Y19: =ABS(F19-G19) -> 5.582
A20: 12787 | B20: Lc12787 | C20: Leporillus conditor | D20: 125.86666 | E20: -31.983337 | F20: 95.0097 | G20: =SUM(H20:X20) -> 96.5837 | H20: 0 | I20: 0 | J20: 0 | K20: 0 | L20: 0 | M20: 0 | N20: 0 | O20: 96.5837 | P20: 0 | Q20: 0 | R20: 0 | S20: 0 | T20: 0 | U20: 0 | V20: 0 | W20: 0 | X20: 0 | Y20: =ABS(F20-G20) -> 1.574
A21: 12679 | B21: Lc12679 | C21: Leporillus conditor | D21: 125.88333 | E21: -32.21667 | F21: 99.9854 | G21: =SUM(H21:X21) -> 80.2412 | H21: 0 | I21: 0 | J21: 0 | K21: 0 | L21: 0 | M21: 0 | N21: 0 | O21: 0 | P21: 0 | Q21: 0 | R21: 80.2412 | S21: 0 | T21: 0 | U21: 0 | V21: 0 | W21: 0 | X21: 0 | Y21: =ABS(F21-G21) -> 19.7442
A22: 12739 | B22: Lc12739 | C22: Leporillus conditor | D22: 125.91667 | E22: -31.96667 | F22: 93.9787 | G22: =SUM(H22:X22) -> 98.8855 | H22: 0 | I22: 0 | J22: 0 | K22: 0 | L22: 0 | M22: 0 | N22: 0 | O22: 98.8855 | P22: 0 | Q22: 0 | R22: 0 | S22: 0 | T22: 0 | U22: 0 | V22: 0 | W22: 0 | X22: 0 | Y22: =ABS(F22-G22) -> 4.9068
A23: 12789 | B23: Lc12789 | C23: Leporillus conditor | D23: 126.03333 | E23: -32.050003 | F23: 93.9782 | G23: =SUM(H23:X23) -> 86.1416 | H23: 0 | I23: 0 | J23: 0 | K23: 0 | L23: 0 | M23: 0 | N23: 0 | O23: 0 | P23: 86.1416 | Q23: 0 | R23: 0 | S23: 0 | T23: 0 | U23: 0 | V23: 0 | W23: 0 | X23: 0 | Y23: =ABS(F23-G23) -> 7.8366
A24: 12714 | B24: Lc12714 | C24: Leporillus conditor | D24: 126.03333 | E24: -32.066675 | F24: 93.9802 | G24: =SUM(H24:X24) -> 81.6311 | H24: 0 | I24: 0 | J24: 0 | K24: 0 | L24: 0 | M24: 0 | N24: 0 | O24: 0 | P24: 81.6311 | Q24: 0 | R24: 0 | S24: 0 | T24: 0 | U24: 0 | V24: 0 | W24: 0 | X24: 0 | Y24: =ABS(F24-G24) -> 12.3491
A25: 12712 | B25: Lc12712 | C25: Leporillus conditor | D25: 126.18332 | E25: -32.033338 | F25: 102.003 | G25: =SUM(H25:X25) -> 90.5368 | H25: 0 | I25: 0 | J25: 0 | K25: 0 | L25: 0 | M25: 0 | N25: 0 | O25: 0 | P25: 90.5368 | Q25: 0 | R25: 0 | S25: 0 | T25: 0 | U25: 0 | V25: 0 | W25: 0 | X25: 0 | Y25: =ABS(F25-G25) -> 11.4662
A26: 12740 | B26: Lc12740 | C26: Leporillus conditor | D26: 126.49999 | E26: -31.98334 | F26: 83.9841 | G26: =SUM(H26:X26) -> 83.5216 | H26: 0 | I26: 0 | J26: 0 | K26: 0 | L26: 0 | M26: 0 | N26: 0 | O26: 0 | P26: 83.5216 | Q26: 0 | R26: 0 | S26: 0 | T26: 0 | U26: 0 | V26: 0 | W26: 0 | X26: 0 | Y26: =ABS(F26-G26) -> 0.4625
A27: 12726 | B27: Lc12726 | C27: Leporillus conditor | D27: 126.73333 | E27: -31.850008 | F27: 111.004 | G27: =SUM(H27:X27) -> 100.037 | H27: 0 | I27: 0 | J27: 0 | K27: 0 | L27: 0 | M27: 0 | N27: 0 | O27: 0 | P27: 100.037 | Q27: 0 | R27: 0 | S27: 0 | T27: 0 | U27: 0 | V27: 0 | W27: 0 | X27: 0 | Y27: =ABS(F27-G27) -> 10.967
A28: 12720 | B28: Lc12720 | C28: Leporillus conditor | D28: 126.79999 | E28: -31.033334 | F28: 178.994 | G28: =SUM(H28:X28) -> 176.604 | H28: 0 | I28: 0 | J28: 0 | K28: 0 | L28: 0 | M28: 0 | N28: 0 | O28: 0 | P28: 176.604 | Q28: 0 | R28: 0 | S28: 0 | T28: 0 | U28: 0 | V28: 0 | W28: 0 | X28: 0 | Y28: =ABS(F28-G28) -> 2.39
A29: 12724 | B29: Lc12724 | C29: Leporillus conditor | D29: 127.01666 | E29: -31.750007 | F29: 102.988 | G29: =SUM(H29:X29) -> 111.7 | H29: 0 | I29: 0 | J29: 0 | K29: 0 | L29: 0 | M29: 0 | N29: 0 | O29: 0 | P29: 111.7 | Q29: 0 | R29: 0 | S29: 0 | T29: 0 | U29: 0 | V29: 0 | W29: 0 | X29: 0 | Y29: =ABS(F29-G29) -> 8.712
A30: 12728 | B30: Lc12728 | C30: Leporillus conditor | D30: 127.03332 | E30: -31.966673 | F30: 64.9803 | G30: =SUM(H30:X30) -> 20.3421 | H30: 0 | I30: 0 | J30: 0 | K30: 0 | L30: 0 | M30: 0 | N30: 0 | O30: 0 | P30: 20.3421 | Q30: 0 | R30: 0 | S30: 0 | T30: 0 | U30: 0 | V30: 0 | W30: 0 | X30: 0 | Y30: =ABS(F30-G30) -> 44.6382
... A52: 13238 | B52: Lc13238 | C52: Leporillus conditor | D52: 128.66666 | E52: -30.483338 | F52: 181.01 | G52: =SUM(H52:X52) -> 176.83 | H52: 0 | I52: 0 | J52: 0 | K52: 0 | L52: 0 | M52: 0 | N52: 0 | O52: 0 | P52: 176.83 | Q52: 0 | R52: 0 | S52: 0 | T52: 0 | U52: 0 | V52: 0 | W52: 0 | X52: 0 | Y52: =ABS(F52-G52) -> 4.18
A53: Baynes2002 | B53: LcBaynes2002 | C53: Leporillus conditor | D53: 128.667 | E53: -30.483 | F53: 180.974 | G53: =SUM(H53:X53) -> 176.894 | H53: 0 | I53: 0 | J53: 0 | K53: 0 | L53: 0 | M53: 0 | N53: 0 | O53: 0 | P53: 176.894 | Q53: 0 | R53: 0 | S53: 0 | T53: 0 | U53: 0 | V53: 0 | W53: 0 | X53: 0 | Y53: =ABS(F53-G53) -> 4.08
A54: 12763 | B54: Lc12763 | C54: Leporillus conditor | D54: 128.74999 | E54: -31.066675 | F54: 162.01 | G54: =SUM(H54:X54) -> 144.764 | H54: 0 | I54: 0 | J54: 0 | K54: 0 | L54: 0 | M54: 0 | N54: 0 | O54: 0 | P54: 144.764 | Q54: 0 | R54: 0 | S54: 0 | T54: 0 | U54: 0 | V54: 0 | W54: 0 | X54: 0 | Y54: =ABS(F54-G54) -> 17.246
A55: 12760 | B55: Lc12760 | C55: Leporillus conditor | D55: 129.03333 | E55: -31.683342 | F55: 0.00200338 | G55: =SUM(H55:X55) -> 0 | H55: 0 | I55: 0 | J55: 0 | K55: 0 | L55: 0 | M55: 0 | N55: 0 | O55: 0 | P55: 0 | Q55: 0 | R55: 0 | S55: 0 | T55: 0 | U55: 0 | V55: 0 | W55: 0 | X55: 0 | Y55: =ABS(F55-G55) -> 0.00200338
A56: 12758 | B56: Lc12758 | C56: Leporillus conditor | D56: 129.1 | E56: -31.533337 | F56: 38.9888 | G56: =SUM(H56:X56) -> 99.8262 | H56: 0 | I56: 0 | J56: 0 | K56: 0 | L56: 0 | M56: 0 | N56: 0 | O56: 0 | P56: 99.8262 | Q56: 0 | R56: 0 | S56: 0 | T56: 0 | U56: 0 | V56: 0 | W56: 0 | X56: 0 | Y56: =ABS(F56-G56) -> 60.8374
A57: 12677 | B57: Lc12677 | C57: Leporillus conditor | D57: 129.25 | E57: -29.750005 | F57: 174.022 | G57: =SUM(H57:X57) -> 195.967 | H57: 0 | I57: 0 | J57: 0 | K57: 0 | L57: 0 | M57: 0 | N57: 0 | O57: 0 | P57: 195.967 | Q57: 0 | R57: 0 | S57: 0 | T57: 0 | U57: 0 | V57: 0 | W57: 0 | X57: 0 | Y57: =ABS(F57-G57) -> 21.945
A58: 12646 | B58: Lc12646 | C58: Leporillus conditor | D58: 129.83333 | E58: -31.400004 | F58: 96.9811 | G58: =SUM(H58:X58) -> 93.4718 | H58: 0 | I58: 0 | J58: 0 | K58: 0 | L58: 0 | M58: 0 | N58: 0 | O58: 0 | P58: 93.4718 | Q58: 0 | R58: 0 | S58: 0 | T58: 0 | U58: 0 | V58: 0 | W58: 0 | X58: 0 | Y58: =ABS(F58-G58) -> 3.5093
A59: 12645 | B59: Lc12645 | C59: Leporillus conditor | D59: 129.91666 | E59: -31.500004 | F59: 58.9706 | G59: =SUM(H59:X59) -> 72.516 | H59: 0 | I59: 0 | J59: 0 | K59: 0 | L59: 0 | M59: 0 | N59: 0 | O59: 0 | P59: 72.516 | Q59: 0 | R59: 0 | S59: 0 | T59: 0 | U59: 0 | V59: 0 | W59: 0 | X59: 0 | Y59: =ABS(F59-G59) -> 13.5454
A60: 12767 | B60: Lc12767 | C60: Leporillus conditor | D60: 130.96666 | E60: -30.550008 | F60: 101.01 | G60: =SUM(H60:X60) -> 114.407 | H60: 0 | I60: 0 | J60: 0 | K60: 0 | L60: 0 | M60: 0 | N60: 0 | O60: 0 | P60: 114.407 | Q60: 0 | R60: 0 | S60: 0 | T60: 0 | U60: 0 | V60: 0 | W60: 0 | X60: 0 | Y60: =ABS(F60-G60) -> 13.397
A61: 12689 | B61: Lc12689 | C61: Leporillus conditor | D61: 131.24999 | E61: -30.250004 | F61: 223.985 | G61: =SUM(H61:X61) -> 103.792 | H61: 0 | I61: 0 | J61: 0 | K61: 0 | L61: 0 | M61: 0 | N61: 0 | O61: 0 | P61: 103.792 | Q61: 0 | R61: 0 | S61: 0 | T61: 0 | U61: 0 | V61: 0 | W61: 0 | X61: 0 | Y61: =ABS(F61-G61) -> 120.193
A62: 12692 | B62: Lc12692 | C62: Leporillus conditor | D62: 131.24999 | E62: -30.583341 | F62: 137.98 | G62: =SUM(H62:X62) -> 102.302 | H62: 0 | I62: 0 | J62: 0 | K62: 0 | L62: 0 | M62: 0 | N62: 0 | O62: 0 | P62: 102.302 | Q62: 0 | R62: 0 | S62: 0 | T62: 0 | U62: 0 | V62: 0 | W62: 0 | X62: 0 | Y62: =ABS(F62-G62) -> 35.678
A63: 12693 | B63: Lc12693 | C63: Leporillus conditor | D63: 131.24999 | E63: -30.583341 | F63: 137.98 | G63: =SUM(H63:X63) -> 102.302 | H63: 0 | I63: 0 | J63: 0 | K63: 0 | L63: 0 | M63: 0 | N63: 0 | O63: 0 | P63: 102.302 | Q63: 0 | R63: 0 | S63: 0 | T63: 0 | U63: 0 | V63: 0 | W63: 0 | X63: 0 | Y63: =ABS(F63-G63) -> 35.678
A64: 12699 | B64: Lc12699 | C64: Leporillus conditor | D64: 131.24999 | E64: -30.583341 | F64: 137.98 | G64: =SUM(H64:X64) -> 102.302 | H64: 0 | I64: 0 | J64: 0 | K64: 0 | L64: 0 | M64: 0 | N64: 0 | O64: 0 | P64: 102.302 | Q64: 0 | R64: 0 | S64: 0 | T64: 0 | U64: 0 | V64: 0 | W64: 0 | X64: 0 | Y64: =ABS(F64-G64) -> 35.678
A65: 12766 | B65: Lc12766 | C65: Leporillus conditor | D65: 131.24999 | E65: -30.583341 | F65: 137.98 | G65: =SUM(H65:X65) -> 102.302 | H65: 0 | I65: 0 | J65: 0 | K65: 0 | L65: 0 | M65: 0 | N65: 0 | O65: 0 | P65: 102.302 | Q65: 0 | R65: 0 | S65: 0 | T65: 0 | U65: 0 | V65: 0 | W65: 0 | X65: 0 | Y65: =ABS(F65-G65) -> 35.678
...

Sheet Separate_Data
A1: Identifier | B1: Species | C1: LONG | D1: Leporillus apicalis | E1: Leporillus conditor | F1: Leporillus
A2: 12688 | B2: Leporillus apicalis | C2: 142.16666 | D2: -34.183342
A3: 12575 | B3: Leporillus apicalis | C3: 142.18333 | D3: -34.16667
A4: 12684 | B4: Leporillus apicalis | C4: 136.16666 | D4: -33.43334
A5: 12678 | B5: Leporillus apicalis | C5: 125.88333 | D5: -32.21667
A6: 12715 | B6: Leporillus apicalis | C6: 126.18333 | D6: -32.1
A7: 12713 | B7: Leporillus apicalis | C7: 126.03333 | D7: -32.066675
A8: 12788 | B8: Leporillus apicalis | C8: 126.03333 | D8: -32.050003
A9: 12785 | B9: Leporillus apicalis | C9: 127.03333 | D9: -31.983341
A10: 12727 | B10: Leporillus apicalis | C10: 127.03332 | D10: -31.966673
A11: 12738 | B11: Leporillus apicalis | C11: 125.91667 | D11: -31.96667
A12: 12725 | B12: Leporillus apicalis | C12: 126.73333 | D12: -31.850008
A13: 12718 | B13: Leporillus apicalis | C13: 127.71666 | D13: -31.833335
... A32: 12661 | B32: Leporillus apicalis | C32: 138.36666 | D32: -30.583334
A33: Baynes2002 | B33: Leporillus apicalis | C33: 120.533 | D33: -30.083
A34: Baynes2002 | B34: Leporillus apicalis | C34: 122.817 | D34: -30.083
A35: Baynes2002 | B35: Leporillus apicalis | C35: 117.25 | D35: -29.567
A36: Baynes2002 | B36: Leporillus apicalis | C36: 121.633 | D36: -29.517
A37: Baynes2002 | B37: Leporillus apicalis | C37: 119.367 | D37: -29.367
A38: Baynes2002 | B38: Leporillus apicalis | C38: 116.767 | D38: -29.2
A39: Baynes2002 | B39: Leporillus apicalis | C39: 115.583 | D39: -29.083
A40: Baynes2002 | B40: Leporillus apicalis | C40: 117.817 | D40: -28.55
A41: Baynes2002 | B41: Leporillus apicalis | C41: 117.183 | D41: -28.133
A42: Baynes2002 | B42: Leporillus apicalis | C42: 115.617 | D42: -28.117
A43: Baynes2002 | B43: Leporillus apicalis | C43: 120.3 | D43: -28.117
A44: Baynes2002 | B44: Leporillus apicalis | C44: 116.283 | D44: -27.467
A45: 13237 | B45: Leporillus apicalis | C45: 126.46666 | D45: -27.200002
A46: Baynes2002 | B46: Leporillus apicalis | C46: 126.467 | D46: -27.2
A47: Baynes2002 | B47: Leporillus apicalis | C47: 119.933 | D47: -27.05
A48: Baynes2002 | B48: Leporillus apicalis | C48: 117.7 | D48: -26.917
A49: 105480 | B49: Leporillus apicalis | C49: 129.93292 | D49: -26.893581
A50: 13236 | B50: Leporillus apicalis | C50: 126.45 | D50: -26.700006
A51: Baynes2002 | B51: Leporillus apicalis | C51: 126.45 | D51: -26.7
A52: 12700 | B52: Leporillus apicalis | C52: 130.66666 | D52: -26.616673
A53: 13235 | B53: Leporillus apicalis | C53: 125.86667 | D53: -26.600004
A54: Baynes2002 | B54: Leporillus apicalis | C54: 113.683 | D54: -26.6
A55: Baynes2002 | B55: Leporillus apicalis | C55: 125.867 | D55: -26.6
A56: Baynes2002 | B56: Leporillus apicalis | C56: 126.033 | D56: -26.517
A57: 13234 | B57: Leporillus apicalis | C57: 126.03333 | D57: -26.516675
A58: Baynes2002 | B58: Leporillus apicalis | C58: 121.05 | D58: -26.417
...

Sheet NPC NT
A1: Search_cod | B1: Family_nam | C1: Taxon_name | D1: Common_nam | E1: Sort_order | F1: Datum | G1: Dec_latitu | H1: Dec_longit | I1: Geo_accura | J1: Begin_obs_ | K1: End_obs_da | L1: Obs_reliab | M1: Observer
A2: Mammal | B2: Muridae | C2: Leporillus apicalis | D2: Lesser Stick-nest Rat | E2: 12055 | F2: AGD66 | G2: -22 | H2: 137.25 | J2: 35329 | K2: 35329 | L2: Observe | M2: Jeff Cole
A3: Mammal | B3: Muridae | C3: Leporillus apicalis | D3: Lesser Stick-nest Rat | E3: 12055 | F3: AGD66 | G3: -23.64 | H3: 133.89 | J3: 31976 | K3: 31976 | L3: Fossil | M3: GJ FYFE
A4: Mammal | B4: Muridae | C4: Leporillus apicalis | D4: Lesser Stick-nest Rat | E4: 12055 | F4: AGD66 | G4: -23.74 | H4: 133.97 | J4: 31829 | K4: 31829 | L4: Fossil | M4: GJ FYFE
A5: Mammal | B5: Muridae | C5: Leporillus apicalis | D5: Lesser Stick-nest Rat | E5: 12055 | F5: AGD66 | G5: -23.66 | H5: 134.33 | I5: 1800 | J5: 31923 | K5: 31923 | L5: Fossil | M5: A SOOS
A6: Mammal | B6: Muridae | C6: Leporillus apicalis | D6: Lesser Stick-nest Rat | E6: 12055 | F6: AGD66 | G6: -23.63 | H6: 134.43 | I6: 1800 | J6: 31941 | K6: 31941 | L6: Fossil | M6: A SOOS
A7: Mammal | B7: Muridae | C7: Leporillus apicalis | D7: Lesser Stick-nest Rat | E7: 12055 | F7: AGD66 | G7: -23.44 | H7: 134.73 | I7: 1000 | J7: 31913 | K7: 31913 | L7: Fossil | M7: AJ BRIDGES
A8: Mammal | B8: Muridae | C8: Leporillus apicalis | D8: Lesser Stick-nest Rat | E8: 12055 | F8: AGD66 | G8: -23.7 | H8: 134.8 | I8: 1000 | J8: 31571 | K8: 31571 | L8: Fossil | M8: KA JOHNSON
A9: Mammal | B9: Muridae | C9: Leporillus apicalis | D9: Lesser Stick-nest Rat | E9: 12055 | F9: AGD66 | G9: -22.35 | H9: 134.88 | I9: 1800 | J9: 31847 | K9: 31847 | L9: Fossil | M9: LOW STRONG
A10: Mammal | B10: Muridae | C10: Leporillus apicalis | D10: Lesser Stick-nest Rat | E10: 12055 | F10: AGD66 | G10: -23.56 | H10: 135.01 | I10: 1800 | J10: 00/08/1989 | K10: 00/08/1989 | L10: Fossil | M10: KA JOHNSON
A11: Mammal | B11: Muridae | C11: Leporillus apicalis | D11: Lesser Stick-nest Rat | E11: 12055 | F11: AGD66 | G11: -22.78 | H11: 135.08 | I11: 1800 | J11: 31846 | K11: 31846 | L11: Fossil | M11: LOW STRONG
A12: Mammal | B12: Muridae | C12: Leporillus apicalis | D12: Lesser Stick-nest Rat | E12: 12055 | F12: AGD66 | G12: -23.85 | H12: 137.16 | I12: 1800 | J12: 31119 | K12: 31119 | L12: Fossil | M12: DF GIBSON
A13: Mammal | B13: Muridae | C13: Leporillus apicalis | D13: Lesser Stick-nest Rat | E13: 12055 | F13: AGD66 | G13: -23.83 | H13: 137.18 | I13: 1800 | J13: 31119 | K13: 31119 | L13: Fossil | M13: DF GIBSON
A14: Mammal | B14: Muridae | C14: Leporillus apicalis | D14: Lesser Stick-nest Rat | E14: 12055 | F14: AGD66 | G14: -22 | H14: 137.25 | J14: 35329 | K14: 35329 | L14: Fossil | M14: Jeff Cole
A15: Mammal | B15: Muridae | C15: Leporillus apicalis | D15: Lesser Stick-nest Rat | E15: 12055 | F15: AGD66 | G15: -22 | H15: 137.32 | J15: 35329 | K15: 35329 | L15: Fossil | M15: Jeff Cole
A16: Mammal | B16: Muridae | C16: Leporillus apicalis | D16: Lesser Stick-nest Rat | E16: 12055 | F16: AGD66 | G16: -23.8 | H16: 130.83 | I16: 1800 | J16: 31624 | K16: 31624 | L16: Fossil | M16: DG LANGFORD
A17: Mammal | B17: Muridae | C17: Leporillus apicalis | D17: Lesser Stick-nest Rat | E17: 12055 | F17: AGD66 | G17: -23.83 | H17: 131.31 | I17: 1800 | J17: 31623 | K17: 31623 | L17: Fossil | M17: DG LANGFORD
A18: Mammal | B18: Muridae | C18: Leporillus apicalis | D18: Lesser Stick-nest Rat | E18: 12055 | F18: AGD66 | G18: -25.35 | H18: 131.03 | I18: 1800 | J18: 00/09/1983 | K18: 00/09/1983 | L18: Fossil | M18: D MATTHEWS
A19: Mammal | B19: Muridae | C19: Leporillus apicalis | D19: Lesser Stick-nest Rat | E19: 12055 | F19: AGD66 | G19: -25.35 | H19: 131.03 | I19: 1800 | J19: 00/09/1983 | K19: 00/09/1983 | L19: Fossil | M19: D MATTHEWS
A20: Mammal | B20: Muridae | C20: Leporillus apicalis | D20: Lesser Stick-nest Rat | E20: 12055 | F20: AGD66 | G20: -25.35 | H20: 131.03 | J20: 0/9/1983 | K20: 0/9/1983 | L20: Voucher | M20: Dennis Matthews
A21: Mammal | B21: Muridae | C21: Leporillus apicalis | D21: Lesser Stick-nest Rat | E21: 12055 | F21: AGD66 | G21: -25.35 | H21: 131.03 | J21: 0/9/1983 | K21: 0/9/1983 | L21: Voucher | M21: Dennis Matthews
A22: Mammal | B22: Muridae | C22: Leporillus apicalis | D22: Lesser Stick-nest Rat | E22: 12055 | F22: AGD66 | G22: -24.03 | H22: 133.41 | I22: 250 | J22: 33147 | K22: 33147 | L22: Sign | M22: K LEHMANN
A23: Mammal | B23: Muridae | C23: Leporillus apicalis | D23: Lesser Stick-nest Rat | E23: 12055 | F23: AGD66 | G23: -25.96 | H23: 133.86 | I23: 1800 | J23: 31617 | K23: 31617 | L23: Fossil | M23: MJ FREEMAN
A24: Mammal | B24: Muridae | C24: Leporillus apicalis | D24: Lesser Stick-nest Rat | E24: 12055 | F24: AGD66 | G24: -25.98 | H24: 133.9 | I24: 1800 | J24: 31617 | K24: 31617 | L24: Fossil | M24: MJ FREEMAN
A25: Mammal | B25: Muridae | C25: Leporillus apicalis | D25: Lesser Stick-nest Rat | E25: 12055 | F25: AGD66 | G25: -24.56 | H25: 135.75 | I25: 1800 | J25: 31352 | K25: 31352 | L25: Fossil | M25: DF GIBSON

Sheet FossilMiddens
A1: Author's description | B1: Publication date | C1: Author | D1: geology | E1: plants | F1: Latitude | G1: Longitude | H1: Latitude | I1: Longitude | J1: Location (State) | K1: Institution (University of New South Wales, University of Wollongong) | L1: Age estimate | N1: STDEV | O1: RADIOCARBON LAB. | Q1: TYPE OF ANALYSIS | R1: MATERIAL ANALYSED | S1: MATERIAL ANALYSED | T1: DELTA13 CORRECTION (if known) | U1: PHYSICAL PRETREATMENT | V1: CHEMICAL PRETREATMENT | W1: POSITION | X1: Builder
A2: ARLTP5 | B2: 2002 | C2: Webeck | D2: Quartzite | H2: 134.7 | I2: -23.45 | J2: Arltunga | K2: University of Newcastle | L2: Modern | O2: Waikato9583 | Q2: Conventional | R2: SNR scats | X2: Leporillis apicalis
A3: ARLT01 | B3: 2002 | C3: Webeck | H3: 134.7 | I3: -23.45 | J3: Arltunga | K3: University of Newcastle | L3: Modern | O3: Waikato9584 | Q3: Conventional | R3: SNR scats | X3: Leporillis apicalis
A4: ARLTN15 | B4: 2002 | C4: Webeck | H4: 134.7 | I4: -23.45 | J4: Arltunga | K4: University of Newcastle | L4: 433 | M4: + | N4: 60 | O4: Waikato9585 | Q4: Conventional | R4: SNR scats | X4: Leporillis apicalis
A5: ARLTH10 | B5: 2002 | C5: Webeck | H5: 134.7 | I5: -23.45 | J5: Arltunga | K5: University of Newcastle | L5: 606 | M5: + | N5: 136 | O5: Waikato9581 | Q5: Conventional | R5: SNR scats | X5: Leporillis apicalis
A6: ARLTK2 | B6: 2002 | C6: Webeck | H6: 134.7 | I6: -23.45 | J6: Arltunga | K6: University of Newcastle | L6: 835 | M6: + | N6: 62 | O6: Waikato9582 | Q6: Conventional | R6: SNR scats | X6: Leporillis apicalis
A7: ARLTG8 | B7: 2002 | C7: Webeck | H7: 134.7 | I7: -23.45 | J7: Arltunga | K7: University of Newcastle | L7: 2500 | M7: + | N7: 40 | O7: OZF197 | Q7: AMS | R7: SNR scats | X7: Leporillis apicalis
A8: FinkeG15 | B8: 2002 | C8: Cockerill | G8: 132.2 | H8: 132.2 | I8: -24.433333 | J8: Amphitheatre | K8: University of Newcastle | L8: 360 | M8: + | N8: 82 | O8: Waikato | Q8: Conventional | R8: SNR scats
A9: FinkeI16 | B9: 2002 | C9: Cockerill | H9: 132.2 | I9: -24.433333 | J9: Amphitheatre | K9: University of Newcastle | L9: 552 | M9: + | N9: 128 | O9: Waikato | Q9: Conventional | R9: SNR scats
A10: FinkeA22 | B10: 2002 | C10: Cockerill | H10: 132.2 | I10: -24.433333 | J10: Amphitheatre | K10: University of Newcastle | L10: 756 | M10: + | N10: 78 | O10: Waikato | Q10: Conventional | R10: SNR scats
A11: FinkeH19 | B11: 2002 | C11: Cockerill | H11: 132.2 | I11: -24.433333 | J11: Amphitheatre | K11: University of Newcastle | L11: 988 | M11: + | N11: 66 | O11: Waikato | Q11: Conventional | R11: SNR scats
A12: FinkeF4 | B12: 2002 | C12: Cockerill | H12: 132.2 | I12: -24.433333 | J12: Amphitheatre | K12: University of Newcastle | L12: 3090 | M12: + | N12: 65 | O12: Waikato | Q12: Conventional | R12: SNR scats
A13: Pearson2002 | J13: Coonabarabran | L13: undated
A14: Nelson et al (1990) , | B14: 1990 | C14: Nelson | E14: ad | F14: 24 | G14: 133 | H14: 133 | I14: -24 | J14: Finke Gorge (NT) | K14: A3990 | L14: -2780 | M14: + | N14: 100 | O14: A3990 | Q14: Conventional | S14: ? | W14: B
A15: Nelson et al (1990) , | B15: 1990 | C15: Nelson | E15: ad | F15: 24 | G15: 133 | H15: 133 | I15: -24 | J15: Finke Gorge (NT) | K15: A3989 | L15: -1660 | M15: + | N15: 100 | O15: A3989 | Q15: Conventional | S15: ? | W15: T
A16: M0236 | B16: 1993 | C16: Pearson & Dodson | E16: ab | F16: 30 30' | G16: 119 40' | H16: 119.66667 | I16: -30.5 | J16: Bungalbin Hill (WA) | K16: UNSW | L16: -340 | M16: + | N16: 55 | O16: OZB166 | P16: 1 | Q16: AMS | R16: SCAT | S16: SCAT | T16: -25 | U16: Crushed, sieved particles greater than 0.2mm retained. For larger samples fibrous materials removed for dating. For smaller samples all sieve material used. | V16: AAA treatment: 2M HCl at 60oC for 5 hours then room temperature for 15 hours, 2% NaOH at 60oC for 5 hours then room temperature for 15 hours, 2M HCl at 60oC for 5 hours then washed in deionised water. | W16: B
A17: CRA9 | B17: 1997 | C17: Pearson | E17: 6 | F17: 23 30' | G17: 134 30' | H17: 134.5 | I17: -23.5 | J17: Cavenagh Range (WA) | K17: UNSW | L17: -2400 | M17: + | N17: 290 | O17: OZA980 | P17: 1 | Q17: AMS | R17: SCAT | S17: SCAT | T17: -25 | U17: Crushed, sieved particles greater than 0.2mm retained. For larger samples fibrous materials removed for dating. For smaller samples all sieve material used. | V17: AAA treatment: 2M HCl at 60oC for 5 hours then room temperature for 15 hours, 2% NaOH at 60oC for 5 hours then room temperature for 15 hours, 2M HCl at 60oC for 5 hours then washed in deionised water. | W17: A
A18: Berry (1993) | B18: 1993 | C18: Berry | E18: 2 | F18: 24 19 | G18: 131 41 | H18: 131.68333 | I18: -24.316667 | K18: MaqU | L18: -3500 | M18: + | N18: 90 | O18: BETA-23022 | Q18: Conventional | R18: PLANT FRAGMENTS | S18: PLANT FRAGMENTS | W18: B | Y18: OZA318 (one result only) 10900 +- 90
A19: Berry (1993) | B19: 1993 | C19: Berry | E19: 2 | F19: 24 19 | G19: 131 41 | H19: 131.68333 | I19: -24.316667 | K19: MaqU | L19: -1700 | M19: + | N19: 90 | O19: BETA-23023 | Q19: Conventional | R19: PLANT FRAGMENTS | S19: PLANT FRAGMENTS | W19: T
A20: M0505 | B20: 1993 | C20: Pearson & Dodson | E20: ac | F20: 25 03' | G20: 124 59' | H20: 124.98333 | I20: -25.05 | J20: Young Range, Gibson Desert (WA) | K20: UNSW | L20: -710 | M20: + | N20: 80 | O20: BETA-30955 | Q20: Conventional | R20: PLANT FRAGMENTS | S20: PLANT FRAGMENTS | T20: -25 | W20: B
A21: M05170b | B21: 1993 | C21: Pearson & Dodson | E21: ac | F21: 25 03' | G21: 124 59' | H21: 124.98333 | I21: -25.05 | J21: Young Range, Gibson Desert (WA) | K21: UNSW | L21: -800 | M21: + | N21: 80 | O21: BETA-68230 | Q21: Conventional | R21: PLANT FRAGMENTS | S21: PLANT FRAGMENTS | T21: -25 | W21: A
A22: M06 | B22: 1993 | C22: Pearson & Dodson | E22: ac | F22: 25 03' | G22: 124 59' | H22: 124.98333 | I22: -25.05 | J22: Young Range, Gibson Desert (WA) | K22: UNSW | L22: -1150 | M22: + | N22: 100 | O22: BETA-30956 | Q22: Conventional | R22: PLANT FRAGMENTS | S22: PLANT FRAGMENTS | T22: -25 | W22: B
A23: M0652 | B23: 1993 | C23: Pearson & Dodson | E23: ac | F23: 25 03' | G23: 124 59' | H23: 124.98333 | I23: -25.05 | J23: Young Range, Gibson Desert (WA) | K23: UNSW | L23: -900 | M23: + | N23: 45 | O23: OZA167U | P23: 1 | Q23: AMS | R23: SCAT | S23: SCAT | T23: -25 | W23: A
A24: M07 | B24: 1993 | C24: Pearson & Dodson | E24: ac | F24: 25 03' | G24: 124 59' | H24: 124.98333 | I24: -25.05 | J24: Young Range, Gibson Desert (WA) | K24: UNSW | L24: -900 | M24: + | N24: 90 | O24: BETA-30957 | Q24: Conventional | R24: SCAT | S24: SCAT | T24: -25 | W24: M
A25: M07 | B25: 1993 | C25: Pearson & Dodson | E25: ac | F25: 25 03' | G25: 124 59' | H25: 124.98333 | I25: -25.05 | J25: Young Range, Gibson Desert (WA) | K25: UNSW | L25: -300 | M25: + | N25: 90 | O25: BETA-30958 | Q25: Conventional | R25: PLANT FRAGMENTS | S25: PLANT FRAGMENTS | T25: -25 | W25: T
A26: USA127 | B26: 1997 | C26: Pearson | E26: ag | F26: 25 49'48" | G26: 134 11'54" | H26: 134.19833 | I26: -25.83 | J26: Umbeara Station (NT) | K26: UNSW | L26: -610 | M26: + | N26: 40 | O26: OZA973U | P26: 1 | Q26: AMS | R26: SCAT | S26: SCAT | T26: -25 | U26: Crushed, sieved particles greater than 0.2mm retained. For larger samples fibrous materials removed for dating. For smaller samples all sieve material used. | V26: AAA treatment: 2M HCl at 60oC for 5 hours then room temperature for 15 hours, 2% NaOH at 60oC for 5 hours then room temperature for 15 hours, 2M HCl at 60oC for 5 hours then washed in deionised water. | W26: M
A27: USA131 | B27: 1997 | C27: Pearson | E27: ag | F27: 25 49'48" | G27: 134 11'54" | H27: 134.19833 | I27: -25.83 | J27: Umbeara Station (NT) | K27: UNSW | L27: -200 | M27: + | N27: 55 | O27: OZA972 | P27: 1 | Q27: AMS | R27: SCAT | S27: SCAT | T27: -25 | U27: Crushed, sieved particles greater than 0.2mm retained. For larger samples fibrous materials removed for dating. For smaller samples all sieve material used. | V27: AAA treatment: 2M HCl at 60oC for 5 hours then room temperature for 15 hours, 2% NaOH at 60oC for 5 hours then room temperature for 15 hours, 2M HCl at 60oC for 5 hours then washed in deionised water. | W27: T
A28: USA16 | B28: 1997 | C28: Pearson | E28: ag | F28: 25 49'48" | G28: 134 11'54" | H28: 134.19833 | I28: -25.83 | J28: Umbeara Station (NT) | K28: UNSW | L28: -2280 | M28: + | N28: 120 | O28: OZA186U | P28: 1 | Q28: AMS | R28: SCAT | S28: SCAT | T28: -25 | U28: Crushed, sieved particles greater than 0.2mm retained. For larger samples fibrous materials removed for dating. For smaller samples all sieve material used. | V28: AAA treatment: 2M HCl at 60oC for 5 hours then room temperature for 15 hours, 2% NaOH at 60oC for 5 hours then room temperature for 15 hours, 2M HCl at 60oC for 5 hours then washed in deionised water. | W28: B
A29: USA22 | B29: 1997 | C29: Pearson | E29: ag | F29: 25 49'48" | G29: 134 11'54" | H29: 134.19833 | I29: -25.83 | J29: Umbeara Station (NT) | K29: UNSW | L29: -2330 | M29: + | N29: 120 | O29: OZA187 | P29: 1 | Q29: AMS | R29: ACACIA PHYLLODE | S29: LEAF | T29: -27 | U29: No physical pretreatment | V29: AAA treatment: 2M HCl at 60oC for 5 hours then room temperature for 15 hours, 2% NaOH at 60oC for 5 hours then room temperature for 15 hours, 2M HCl at 60oC for 5 hours then washed in deionised water. | W29: B
A30: USB10 | B30: 1997 | C30: Pearson | E30: ag | F30: 25 49'48" | G30: 134 11'54" | H30: 134.19833 | I30: -25.83 | J30: Umbeara Station (NT) | K30: UNSW | L30: -3350 | M30: + | N30: 80 | O30: OZA188U2 | P30: 1 | Q30: AMS | R30: SCAT | S30: SCAT | T30: -25 | U30: Crushed, sieved particles greater than 0.2mm retained. For larger samples fibrous materials removed for dating. For smaller samples all sieve material used. | V30: AAA treatment: 2M HCl at 60oC for 5 hours then room temperature for 15 hours, 2% NaOH at 60oC for 5 hours then room temperature for 15 hours, 2M HCl at 60oC for 5 hours then washed in deionised water. | W30: A
A31: USB10 | B31: 1997 | C31: Pearson | E31: ag | F31: 25 49'48" | G31: 134 11'54" | H31: 134.19833 | I31: -25.83 | J31: Umbeara Station (NT) | K31: UNSW | L31: -3310 | M31: + | N31: 80 | O31: OZA188U1 | P31: 1 | Q31: AMS | R31: SCAT | S31: SCAT | T31: -25 | U31: Crushed, sieved particles greater than 0.2mm retained. For larger samples fibrous materials removed for dating. For smaller samples all sieve material used. | V31: AAA treatment: 2M HCl at 60oC for 5 hours then room temperature for 15 hours, 2% NaOH at 60oC for 5 hours then room temperature for 15 hours, 2M HCl at 60oC for 5 hours then washed in deionised water. | W31: A
A32: USB11 | B32: 1997 | C32: Pearson | E32: ag | F32: 25 49'48" | G32: 134 11'54" | H32: 134.19833 | I32: -25.83 | J32: Umbeara Station (NT) | K32: UNSW | L32: -3450 | M32: + | N32: 70 | O32: OZA189 | P32: 1 | Q32: AMS | R32: AMBERAT | S32: AMBERAT | T32: -23.8 | W32: A
A33: USB13 | B33: 1997 | C33: Pearson | E33: ag | F33: 25 49'48" | G33: 134 11'54" | H33: 134.19833 | I33: -25.83 | J33: Umbeara Station (NT) | K33: UNSW | L33: -3330 | M33: + | N33: 190 | O33: OZA190 | P33: 1 | Q33: AMS | R33: ACACIA PHYLLODE | S33: LEAF | T33: -24.4 | U33: No physical pretreatment | V33: AAA treatment: 2M HCl at 60oC for 5 hours then room temperature for 15 hours, 2% NaOH at 60oC for 5 hours then room temperature for 15 hours, 2M HCl at 60oC for 5 hours then washed in deionised water. | W33: A
A34: USC191 | B34: 1997 | C34: Pearson | E34: ag | F34: 25 49'48" | G34: 134 11'54" | H34: 134.19833 | I34: -25.83 | J34: Umbeara Station (NT) | K34: UNSW | L34: NOT DATABLE | M34: + | O34: ANSTO | Q34: AMS | R34: SCAT | S34: SCAT | T34: -25
A35: USC31 | B35: 1997 | C35: Pearson | E35: ag | F35: 25 49'48" | G35: 134 11'54" | H35: 134.19833 | I35: -25.83 | J35: Umbeara Station (NT) | K35: UNSW | L35: 101.55pMC+ 0.4% | M35: + | N35: 0 | O35: OZA191 | P35: 1 | Q35: AMS | R35: SKIN | S35: SKIN | T35: -21.8 | U35: No physical treatment | V35: 2M HCl at 60oC for 1 hour, then at room te,perature for 15 hours, washed in deionised water | W35: T
A36: USC39 | B36: 1997 | C36: Pearson | E36: ag | F36: 25 49'48" | G36: 134 11'54" | H36: 134.19833 | I36: -25.83 | J36: Umbeara Station (NT) | K36: UNSW | L36: -410 | M36: + | N36: 165 | O36: OZA192 | P36: 1 | Q36: AMS | R36: ACACIA PHYLLODE | S36: LEAF | T36: -27 | U36: No physical pretreatment | V36: AAA treatment: 2M HCl at 60oC for 5 hours then room temperature for 15 hours, 2% NaOH at 60oC for 5 hours then room temperature for 15 hours, 2M HCl at 60oC for 5 hours then washed in deionised water. | W36: T
A37: USC89 | B37: 1997 | C37: Pearson | E37: ag | F37: 25 49'48" | G37: 134 11'54" | H37: 134.19833 | I37: -25.83 | J37: Umbeara Station (NT) | K37: UNSW | L37: -250 | M37: + | N37: 60 | O37: BETA-76573 | Q37: Conventional | R37: PLANT FRAGMENTS | S37: PLANT FRAGMENTS | T37: -25 | W37: T
A38: USC99 | B38: 1997 | C38: Pearson | E38: ag | F38: 25 49'48" | G38: 134 11'54" | H38: 134.19833 | I38: -25.83 | J38: Umbeara Station (NT) | K38: UNSW | L38: 101.1pMC+ 0.7% | M38: + | N38: 0 | O38: BETA-76574 | Q38: Conventional | R38: PLANT FRAGMENTS | S38: PLANT FRAGMENTS | T38: -25 | W38: T
A39: USE72 | B39: 1997 | C39: Pearson | E39: ag | F39: 25 49'48" | G39: 134 11'54" | H39: 134.19833 | I39: -25.83 | J39: Umbeara Station (NT) | K39: UNSW | L39: -1470 | M39: + | N39: 70 | O39: BETA-76575 | Q39: Conventional | R39: PLANT FRAGMENTS | S39: PLANT FRAGMENTS | T39: -25 | W39: A
A40: USF06 | B40: 1997 | C40: Pearson | E40: ag | F40: 25 49'48" | G40: 134 11'54" | H40: 134.19833 | I40: -25.83 | J40: Umbeara Station (NT) | K40: UNSW | L40: -310 | M40: + | N40: 40 | O40: OZA961U | P40: 1 | Q40: AMS | R40: SCAT | S40: SCAT | T40: -25 | U40: Crushed, sieved particles greater than 0.2mm retained. For larger samples fibrous materials removed for dating. For smaller samples all sieve material used. | V40: AAA treatment: 2M HCl at 60oC for 5 hours then room temperature for 15 hours, 2% NaOH at 60oC for 5 hours then room temperature for 15 hours, 2M HCl at 60oC for 5 hours then washed in deionised water. | W40: A
...

Sheet all records
A1: Identifier | B1: Species | C1: LONG | D1: LAT | E1: Location data
A2: Baynes2002 | B2: Leporillus apicalis | C2: 113.3 | D2: -26.4 | E2: False Entrance Well
A3: Baynes2002 | B3: Leporillus apicalis | C3: 113.433 | D3: -24.117 | E3: Coastal cliffs
A4: Baynes2002 | B4: Leporillus apicalis | C4: 113.583 | D4: -25.633 | E4: Guichenault Point
A5: Baynes2002 | B5: Leporillus apicalis | C5: 113.683 | D5: -26.6 | E5: Baba Head
A6: Baynes2002 | B6: Leporillus apicalis | C6: 113.8 | D6: -23.117 | E6: Limestone ridge SE of Cardabia Hstd
A7: Baynes2002 | B7: Leporillus apicalis | C7: 113.983 | D7: -22.2 | E7: Cave C-207 Cape Range
A8: Baynes2002 | B8: Leporillus apicalis | C8: 113.983 | D8: -22.183 | E8: Cave C-4 Cape Range
A9: Baynes2002 | B9: Leporillus apicalis | C9: 114 | D9: -22.217 | E9: Cave C-200 Cape Range
A10: Baynes2002 | B10: Leporillus apicalis | C10: 114 | D10: -22.133 | E10: Cave C-299 Cape Range
A11: Baynes2002 | B11: Leporillus apicalis | C11: 114.033 | D11: -22.017 | E11: Cave C-251 Cape Range
A12: Baynes2002 | B12: Leporillus apicalis | C12: 114.283 | D12: -25.983 | E12: Bluffs near Yaringa Homestead
A13: Baynes2002 | B13: Leporillus apicalis | C13: 115.15 | D13: -25.35 | E13: Breakaway on Winderie Station
... A35: Baynes2002 | B35: Leporillus apicalis | C35: 124.983 | D35: -25.033 | E35: Young Range
A36: 13235 | B36: Leporillus apicalis | C36: 125.86667 | D36: -26.600004
A37: Baynes2002 | B37: Leporillus apicalis | C37: 125.867 | D37: -26.6 | E37: Breakaways near Gahnda Rockhole
A38: 12678 | B38: Leporillus apicalis | C38: 125.88333 | D38: -32.21667
A39: 12738 | B39: Leporillus apicalis | C39: 125.91667 | D39: -31.96667
A40: Baynes2002 | B40: Leporillus apicalis | C40: 125.933 | D40: -25.767 | E40: Mount Samuel
A41: 13233 | B41: Leporillus apicalis | C41: 125.93333 | D41: -25.766668
A42: Baynes2002 | B42: Leporillus apicalis | C42: 126.033 | D42: -26.517 | E42: Breakaways near Winduldurra Rockhole
A43: 13234 | B43: Leporillus apicalis | C43: 126.03333 | D43: -26.516675
A44: 12788 | B44: Leporillus apicalis | C44: 126.03333 | D44: -32.050003
A45: 12713 | B45: Leporillus apicalis | C45: 126.03333 | D45: -32.066675
A46: 12715 | B46: Leporillus apicalis | C46: 126.18333 | D46: -32.1
A47: 13236 | B47: Leporillus apicalis | C47: 126.45 | D47: -26.700006
A48: Baynes2002 | B48: Leporillus apicalis | C48: 126.45 | D48: -26.7 | E48: Manton Knob
A49: 13237 | B49: Leporillus apicalis | C49: 126.46666 | D49: -27.200002
A50: Baynes2002 | B50: Leporillus apicalis | C50: 126.467 | D50: -27.2 | E50: Point Wood
A51: 12725 | B51: Leporillus apicalis | C51: 126.73333 | D51: -31.850008
A52: 12723 | B52: Leporillus apicalis | C52: 127.01666 | D52: -31.583339
A53: 12727 | B53: Leporillus apicalis | C53: 127.03332 | D53: -31.966673
A54: 12785 | B54: Leporillus apicalis | C54: 127.03333 | D54: -31.983341
A55: 12747 | B55: Leporillus apicalis | C55: 127.18333 | D55: -31.433337
A56: 12695 | B56: Leporillus apicalis | C56: 127.43333 | D56: -31.650001
A57: 12721 | B57: Leporillus apicalis | C57: 127.43333 | D57: -31.650001
A58: 12718 | B58: Leporillus apicalis | C58: 127.71666 | D58: -31.833335
A59: 12750 | B59: Leporillus apicalis | C59: 127.71666 | D59: -31.683341
A60: 12768 | B60: Leporillus apicalis | C60: 127.79999 | D60: -31.775005
A61: 12716 | B61: Leporillus apicalis | C61: 127.8 | D61: -31.76667
...

Sheet Sheet1
A2: Study Location File Upload
A4: SHaRED can process study location coordinates provided in a csv file (comma-separated values file). For more information on how to create a csv file with Microsoft Excel, please use this link.
A6: The csv file must comply with the following requirements:
A8: The file needs to be composed of the following columns (in this order):
A9: study location identifier, x coordinate, y coordinate, zone, comments
A11: Column headers are not required.
A12: The 'zone' and 'comments' values are optional, but the file should contain empty strings ("") in their place.
A14: The following text is a row from a study location file in csv format without 'zone' and 'comments' values:
A15: NTBHR001,137.34,-38.33,"",""
A17: Study Location File:
A18: Description:
A19: Coordinate System:

Sheet SHaRED
A1: Identifier | B1: Species | D1: LONG | E1: LAT | F1: Location data
A2: Baynes2002 | B2: Leporillus apicalis | C2: =A2&" "&B2&" "&F2&" "&G2 -> Baynes2002 Leporillus apicalis False Entrance Well | D2: 113.3 | E2: -26.4 | F2: False Entrance Well
A3: Baynes2002 | B3: Leporillus apicalis | C3: =A3&" "&B3&" "&F3&" "&G3 -> Baynes2002 Leporillus apicalis Coastal cliffs | D3: 113.433 | E3: -24.117 | F3: Coastal cliffs
A4: Baynes2002 | B4: Leporillus apicalis | C4: =A4&" "&B4&" "&F4&" "&G4 -> Baynes2002 Leporillus apicalis Guichenault Point | D4: 113.583 | E4: -25.633 | F4: Guichenault Point
A5: Baynes2002 | B5: Leporillus apicalis | C5: =A5&" "&B5&" "&F5&" "&G5 -> Baynes2002 Leporillus apicalis Baba Head | D5: 113.683 | E5: -26.6 | F5: Baba Head
A6: Baynes2002 | B6: Leporillus apicalis | C6: =A6&" "&B6&" "&F6&" "&G6 -> Baynes2002 Leporillus apicalis Limestone ridge SE of Cardabia Hstd | D6: 113.8 | E6: -23.117 | F6: Limestone ridge SE of Cardabia Hstd
A7: Baynes2002 | B7: Leporillus apicalis | C7: =A7&" "&B7&" "&F7&" "&G7 -> Baynes2002 Leporillus apicalis Cave C-207 Cape Range | D7: 113.983 | E7: -22.2 | F7: Cave C-207 Cape Range
A8: Baynes2002 | B8: Leporillus apicalis | C8: =A8&" "&B8&" "&F8&" "&G8 -> Baynes2002 Leporillus apicalis Cave C-4 Cape Range | D8: 113.983 | E8: -22.183 | F8: Cave C-4 Cape Range
A9: Baynes2002 | B9: Leporillus apicalis | C9: =A9&" "&B9&" "&F9&" "&G9 -> Baynes2002 Leporillus apicalis Cave C-200 Cape Range | D9: 114 | E9: -22.217 | F9: Cave C-200 Cape Range
A10: Baynes2002 | B10: Leporillus apicalis | C10: =A10&" "&B10&" "&F10&" "&G10 -> Baynes2002 Leporillus apicalis Cave C-299 Cape Range | D10: 114 | E10: -22.133 | F10: Cave C-299 Cape Range
A11: Baynes2002 | B11: Leporillus apicalis | C11: =A11&" "&B11&" "&F11&" "&G11 -> Baynes2002 Leporillus apicalis Cave C-251 Cape Range | D11: 114.033 | E11: -22.017 | F11: Cave C-251 Cape Range
A12: Baynes2002 | B12: Leporillus apicalis | C12: =A12&" "&B12&" "&F12&" "&G12 -> Baynes2002 Leporillus apicalis Bluffs near Yaringa Homestead | D12: 114.283 | E12: -25.983 | F12: Bluffs near Yaringa Homestead
A13: Baynes2002 | B13: Leporillus apicalis | C13: =A13&" "&B13&" "&F13&" "&G13 -> Baynes2002 Leporillus apicalis Breakaway on Winderie Station | D13: 115.15 | E13: -25.35 | F13: Breakaway on Winderie Station
... A35: Baynes2002 | B35: Leporillus apicalis | C35: =A35&" "&B35&" "&F35&" "&G35 -> Baynes2002 Leporillus apicalis Young Range | D35: 124.983 | E35: -25.033 | F35: Young Range
A36: 13235 | B36: Leporillus apicalis | C36: =A36&" "&B36&" "&F36&" "&G36 -> 13235 Leporillus apicalis | D36: 125.86667 | E36: -26.600004
A37: Baynes2002 | B37: Leporillus apicalis | C37: =A37&" "&B37&" "&F37&" "&G37 -> Baynes2002 Leporillus apicalis Breakaways near Gahnda Rockhole | D37: 125.867 | E37: -26.6 | F37: Breakaways near Gahnda Rockhole
A38: 12678 | B38: Leporillus apicalis | C38: =A38&" "&B38&" "&F38&" "&G38 -> 12678 Leporillus apicalis | D38: 125.88333 | E38: -32.21667
A39: 12738 | B39: Leporillus apicalis | C39: =A39&" "&B39&" "&F39&" "&G39 -> 12738 Leporillus apicalis | D39: 125.91667 | E39: -31.96667
A40: Baynes2002 | B40: Leporillus apicalis | C40: =A40&" "&B40&" "&F40&" "&G40 -> Baynes2002 Leporillus apicalis Mount Samuel | D40: 125.933 | E40: -25.767 | F40: Mount Samuel
A41: 13233 | B41: Leporillus apicalis | C41: =A41&" "&B41&" "&F41&" "&G41 -> 13233 Leporillus apicalis | D41: 125.93333 | E41: -25.766668
A42: Baynes2002 | B42: Leporillus apicalis | C42: =A42&" "&B42&" "&F42&" "&G42 -> Baynes2002 Leporillus apicalis Breakaways near Winduldurra Rockhole | D42: 126.033 | E42: -26.517 | F42: Breakaways near Winduldurra Rockhole
A43: 13234 | B43: Leporillus apicalis | C43: =A43&" "&B43&" "&F43&" "&G43 -> 13234 Leporillus apicalis | D43: 126.03333 | E43: -26.516675
A44: 12788 | B44: Leporillus apicalis | C44: =A44&" "&B44&" "&F44&" "&G44 -> 12788 Leporillus apicalis | D44: 126.03333 | E44: -32.050003
A45: 12713 | B45: Leporillus apicalis | C45: =A45&" "&B45&" "&F45&" "&G45 -> 12713 Leporillus apicalis | D45: 126.03333 | E45: -32.066675
A46: 12715 | B46: Leporillus apicalis | C46: =A46&" "&B46&" "&F46&" "&G46 -> 12715 Leporillus apicalis | D46: 126.18333 | E46: -32.1
A47: 13236 | B47: Leporillus apicalis | C47: =A47&" "&B47&" "&F47&" "&G47 -> 13236 Leporillus apicalis | D47: 126.45 | E47: -26.700006
A48: Baynes2002 | B48: Leporillus apicalis | C48: =A48&" "&B48&" "&F48&" "&G48 -> Baynes2002 Leporillus apicalis Manton Knob | D48: 126.45 | E48: -26.7 | F48: Manton Knob
A49: 13237 | B49: Leporillus apicalis | C49: =A49&" "&B49&" "&F49&" "&G49 -> 13237 Leporillus apicalis | D49: 126.46666 | E49: -27.200002
A50: Baynes2002 | B50: Leporillus apicalis | C50: =A50&" "&B50&" "&F50&" "&G50 -> Baynes2002 Leporillus apicalis Point Wood | D50: 126.467 | E50: -27.2 | F50: Point Wood
A51: 12725 | B51: Leporillus apicalis | C51: =A51&" "&B51&" "&F51&" "&G51 -> 12725 Leporillus apicalis | D51: 126.73333 | E51: -31.850008
A52: 12723 | B52: Leporillus apicalis | C52: =A52&" "&B52&" "&F52&" "&G52 -> 12723 Leporillus apicalis | D52: 127.01666 | E52: -31.583339
A53: 12727 | B53: Leporillus apicalis | C53: =A53&" "&B53&" "&F53&" "&G53 -> 12727 Leporillus apicalis | D53: 127.03332 | E53: -31.966673
A54: 12785 | B54: Leporillus apicalis | C54: =A54&" "&B54&" "&F54&" "&G54 -> 12785 Leporillus apicalis | D54: 127.03333 | E54: -31.983341
A55: 12747 | B55: Leporillus apicalis | C55: =A55&" "&B55&" "&F55&" "&G55 -> 12747 Leporillus apicalis | D55: 127.18333 | E55: -31.433337
A56: 12695 | B56: Leporillus apicalis | C56: =A56&" "&B56&" "&F56&" "&G56 -> 12695 Leporillus apicalis | D56: 127.43333 | E56: -31.650001
A57: 12721 | B57: Leporillus apicalis | C57: =A57&" "&B57&" "&F57&" "&G57 -> 12721 Leporillus apicalis | D57: 127.43333 | E57: -31.650001
A58: 12718 | B58: Leporillus apicalis | C58: =A58&" "&B58&" "&F58&" "&G58 -> 12718 Leporillus apicalis | D58: 127.71666 | E58: -31.833335
A59: 12750 | B59: Leporillus apicalis | C59: =A59&" "&B59&" "&F59&" "&G59 -> 12750 Leporillus apicalis | D59: 127.71666 | E59: -31.683341
A60: 12768 | B60: Leporillus apicalis | C60: =A60&" "&B60&" "&F60&" "&G60 -> 12768 Leporillus apicalis | D60: 127.79999 | E60: -31.775005
A61: 12716 | B61: Leporillus apicalis | C61: =A61&" "&B61&" "&F61&" "&G61 -> 12716 Leporillus apicalis | D61: 127.8 | E61: -31.76667
...
